Traceback (most recent call last):
  File "C:\Users\gabri\miniconda3\envs\programacioi\Lib\site-packages\jupyter_cache\executors\utils.py", line 58, in single_nb_execution
    executenb(
  File "C:\Users\gabri\miniconda3\envs\programacioi\Lib\site-packages\nbclient\client.py", line 1204, in execute
    return NotebookClient(nb=nb, resources=resources, km=km, **kwargs).execute()
           ^^^^^^^^^^^^^^^^^^^^^^^^^^^^^^^^^^^^^^^^^^^^^^^^^^^^^^^^^^^^^^^^^^^^^
  File "C:\Users\gabri\miniconda3\envs\programacioi\Lib\site-packages\nbclient\util.py", line 84, in wrapped
    return just_run(coro(*args, **kwargs))
           ^^^^^^^^^^^^^^^^^^^^^^^^^^^^^^^
  File "C:\Users\gabri\miniconda3\envs\programacioi\Lib\site-packages\nbclient\util.py", line 62, in just_run
    return loop.run_until_complete(coro)
           ^^^^^^^^^^^^^^^^^^^^^^^^^^^^^
  File "C:\Users\gabri\miniconda3\envs\programacioi\Lib\asyncio\base_events.py", line 653, in run_until_complete
    return future.result()
           ^^^^^^^^^^^^^^^
  File "C:\Users\gabri\miniconda3\envs\programacioi\Lib\site-packages\nbclient\client.py", line 663, in async_execute
    await self.async_execute_cell(
  File "C:\Users\gabri\miniconda3\envs\programacioi\Lib\site-packages\nbclient\client.py", line 965, in async_execute_cell
    await self._check_raise_for_error(cell, cell_index, exec_reply)
  File "C:\Users\gabri\miniconda3\envs\programacioi\Lib\site-packages\nbclient\client.py", line 862, in _check_raise_for_error
    raise CellExecutionError.from_cell_and_msg(cell, exec_reply_content)
nbclient.exceptions.CellExecutionError: An error occurred while executing the following cell:
------------------
# CreaciÃ³ d'una tupla i us amb funcions
vocals = ('a', 'e', 'i', 'o', 'u')

# Operadors
hi_es = 'u' in vocals

print(hi_es)


long = len(vocals)
print(long)

maxim = max(vocals)
print(maxim)


# Indexacio
vocals[0] = 'A'
------------------

[1;31m---------------------------------------------------------------------------[0m
[1;31mTypeError[0m                                 Traceback (most recent call last)
Cell [1;32mIn[1], line 18[0m
[0;32m     14[0m [38;5;28mprint[39m(maxim)
[0;32m     17[0m [38;5;66;03m# Indexacio[39;00m
[1;32m---> 18[0m vocals[[38;5;241m0[39m] [38;5;241m=[39m [38;5;124m'[39m[38;5;124mA[39m[38;5;124m'[39m

[1;31mTypeError[0m: 'tuple' object does not support item assignment
TypeError: 'tuple' object does not support item assignment

