Traceback (most recent call last):
  File "C:\Users\gabri\miniconda3\envs\programacioi\Lib\site-packages\jupyter_cache\executors\utils.py", line 58, in single_nb_execution
    executenb(
  File "C:\Users\gabri\miniconda3\envs\programacioi\Lib\site-packages\nbclient\client.py", line 1204, in execute
    return NotebookClient(nb=nb, resources=resources, km=km, **kwargs).execute()
           ^^^^^^^^^^^^^^^^^^^^^^^^^^^^^^^^^^^^^^^^^^^^^^^^^^^^^^^^^^^^^^^^^^^^^
  File "C:\Users\gabri\miniconda3\envs\programacioi\Lib\site-packages\nbclient\util.py", line 84, in wrapped
    return just_run(coro(*args, **kwargs))
           ^^^^^^^^^^^^^^^^^^^^^^^^^^^^^^^
  File "C:\Users\gabri\miniconda3\envs\programacioi\Lib\site-packages\nbclient\util.py", line 62, in just_run
    return loop.run_until_complete(coro)
           ^^^^^^^^^^^^^^^^^^^^^^^^^^^^^
  File "C:\Users\gabri\miniconda3\envs\programacioi\Lib\asyncio\base_events.py", line 653, in run_until_complete
    return future.result()
           ^^^^^^^^^^^^^^^
  File "C:\Users\gabri\miniconda3\envs\programacioi\Lib\site-packages\nbclient\client.py", line 663, in async_execute
    await self.async_execute_cell(
  File "C:\Users\gabri\miniconda3\envs\programacioi\Lib\site-packages\nbclient\client.py", line 965, in async_execute_cell
    await self._check_raise_for_error(cell, cell_index, exec_reply)
  File "C:\Users\gabri\miniconda3\envs\programacioi\Lib\site-packages\nbclient\client.py", line 862, in _check_raise_for_error
    raise CellExecutionError.from_cell_and_msg(cell, exec_reply_content)
nbclient.exceptions.CellExecutionError: An error occurred while executing the following cell:
------------------
print("Calculo de la suma del intervalo a ,b")

num_a = int(input("Escribe a "))
num_b = int(input("Escribe b "))

sumatorio = 0

for i in range(num_a, num_b+1):
    sumatorio = sumatorio + i
    print(i, sumatorio)
    
print("El resultado es: " + str(sumatorio)) 
------------------

[1;31m---------------------------------------------------------------------------[0m
[1;31mStdinNotImplementedError[0m                  Traceback (most recent call last)
Cell [1;32mIn[1], line 3[0m
[0;32m      1[0m [38;5;28mprint[39m([38;5;124m"[39m[38;5;124mCalculo de la suma del intervalo a ,b[39m[38;5;124m"[39m)
[1;32m----> 3[0m num_a [38;5;241m=[39m [38;5;28mint[39m([38;5;28minput[39m([38;5;124m"[39m[38;5;124mEscribe a [39m[38;5;124m"[39m))
[0;32m      4[0m num_b [38;5;241m=[39m [38;5;28mint[39m([38;5;28minput[39m([38;5;124m"[39m[38;5;124mEscribe b [39m[38;5;124m"[39m))
[0;32m      6[0m sumatorio [38;5;241m=[39m [38;5;241m0[39m

File [1;32m~\miniconda3\envs\programacioi\Lib\site-packages\ipykernel\kernelbase.py:1261[0m, in [0;36mKernel.raw_input[1;34m(self, prompt)[0m
[0;32m   1259[0m [38;5;28;01mif[39;00m [38;5;129;01mnot[39;00m [38;5;28mself[39m[38;5;241m.[39m_allow_stdin:
[0;32m   1260[0m     msg [38;5;241m=[39m [38;5;124m"[39m[38;5;124mraw_input was called, but this frontend does not support input requests.[39m[38;5;124m"[39m
[1;32m-> 1261[0m     [38;5;28;01mraise[39;00m StdinNotImplementedError(msg)
[0;32m   1262[0m [38;5;28;01mreturn[39;00m [38;5;28mself[39m[38;5;241m.[39m_input_request(
[0;32m   1263[0m     [38;5;28mstr[39m(prompt),
[0;32m   1264[0m     [38;5;28mself[39m[38;5;241m.[39m_parent_ident[[38;5;124m"[39m[38;5;124mshell[39m[38;5;124m"[39m],
[0;32m   1265[0m     [38;5;28mself[39m[38;5;241m.[39mget_parent([38;5;124m"[39m[38;5;124mshell[39m[38;5;124m"[39m),
[0;32m   1266[0m     password[38;5;241m=[39m[38;5;28;01mFalse[39;00m,
[0;32m   1267[0m )

[1;31mStdinNotImplementedError[0m: raw_input was called, but this frontend does not support input requests.
StdinNotImplementedError: raw_input was called, but this frontend does not support input requests.

